Workbook

Sheet Dashboard
A1: PANDA SHOES INDUSTRY LTD — PURCHASE & PROCUREMENT PERFORMANCE DASHBOARD
A2: ="Report date: "&TEXT(Settings!B4,"dd mmm yyyy")&" | Values in BDT Lakh (1 Lakh = 1,00,000) | Source: Purchase_Register (auto-refresh)" -> Report date: 15 Oct 2026 | Values in BDT Lakh (1 Lakh = 1,00,000) | Source: Purchase_Register (auto-refresh)
A4: PRs Raised | F4: POs Issued | K4: Committed Spend | P4: Paid to Suppliers | U4: Outstanding Payable
A5: =COUNTA(Purchase_Register!$A$6:$A$205) -> 45 | F5: =COUNTA(Purchase_Register!$O$6:$O$205) -> 39 | K5: =SUM(Purchase_Register!$AD$6:$AD$205)/100000 -> 565.19 | P5: =SUM(Purchase_Register!$AI$6:$AI$205)/100000 -> 338.47316 | U5: =SUM(Purchase_Register!$AK$6:$AK$205)/100000 -> 226.71684
A7: Overdue Payable | F7: % Paid | K7: OPEX Committed | P7: CAPEX Committed | U7: Budget Utilisation
A8: =SUMIFS(Purchase_Register!$AK$6:$AK$205,Purchase_Register!$AP$6:$AP$205,">0")/100000 -> 33.237632 | F8: =IFERROR(SUM(Purchase_Register!$AI$6:$AI$205)/SUM(Purchase_Register!$AD$6:$AD$205),0) -> 0.59886615 | K8: =SUMIFS(Purchase_Register!$AD$6:$AD$205,Purchase_Register!$H$6:$H$205,"OPEX")/100000 -> 439.64954 | P8: =SUMIFS(Purchase_Register!$AD$6:$AD$205,Purchase_Register!$H$6:$H$205,"CAPEX")/100000 -> 125.54046 | U8: =IFERROR(Budget_Control!I25/Budget_Control!H25,0) -> 0.44188363
A10: Net Price Variance vs Budget | F10: OTIF Delivery | K10: Avg Days PR → Approval | P10: Avg Days Approval → PO | U10: Avg Lead Time PO → In-house
A11: =SUM(Purchase_Register!$AA$6:$AA$205)/100000 -> 9.6835635 | F11: =IFERROR(COUNTIF(Purchase_Register!$BE$6:$BE$205,"OTIF")/COUNTIF(Purchase_Register!$BE$6:$BE$205,"*OTIF"),0) -> 0.5 | K11: =IFERROR(AVERAGE(Purchase_Register!$AZ$6:$AZ$205),0) -> 2.9285714 | P11: =IFERROR(AVERAGE(Purchase_Register!$BA$6:$BA$205),0) -> 3.0769231 | U11: =IFERROR(AVERAGE(Purchase_Register!$BB$6:$BB$205),0) -> 21.764706
A13: Avg Full Cycle PR → Close | F13: Awaiting Approval | K13: Open POs (not in-house) | P13: Late Deliveries (open + closed) | U13: PO without Approval (control breach)
A14: =IFERROR(AVERAGE(Purchase_Register!$BC$6:$BC$205),0) -> 28.088235 | F14: =COUNTIF(Purchase_Register!$BI$6:$BI$205,"Awaiting Approval") -> 3 | K14: =COUNTIF(Purchase_Register!$BI$6:$BI$205,"PO Issued*")+COUNTIF(Purchase_Register!$BI$6:$BI$205,"Receiving*") -> 5 | P14: =COUNTIF(Purchase_Register!$BD$6:$BD$205,">0") -> 12 | U14: =COUNTIFS(Purchase_Register!$O$6:$O$205,"<>",Purchase_Register!$K$6:$K$205,"<>Approved") -> 0
A16: Savings vs Budget Price | F16: Pending In-house Value | K16: Paid Ahead of Receipt (risk) | P16: In-Full Delivery Rate | U16: High-Priority Actions
A17: =-SUMIF(Purchase_Register!$AA$6:$AA$205,"<0")/100000 -> 3.7346886 | F17: =SUMIFS(Purchase_Register!$AW$6:$AW$205,Purchase_Register!$AY$6:$AY$205,"")/100000 -> 101.05738 | K17: =SUM(Purchase_Register!$AL$6:$AL$205)/100000 -> 42.7851 | P17: =IFERROR(COUNTIFS(Purchase_Register!$BE$6:$BE$205,"*OTIF",Purchase_Register!$AX$6:$AX$205,"All In-house*")/COUNTIF(Purchase_Register!$BE$6:$BE$205,"*OTIF"),0) -> 0.79411765 | U17: =COUNTIF(Purchase_Register!$BL$6:$BL$205,"High") -> 12
A19: ="ACTIONS: "&COUNT(Purchase_Register!$BM$6:$BM$205)&" line(s) — see Action_Tracker" -> ACTIONS: 22 line(s) — see Action_Tracker | F19: =IF(COUNTIF(Purchase_Register!$BJ$6:$BJ$205,"?*")-COUNTIF(Purchase_Register!$BJ$6:$BJ$205,"OK")=0,"DATA CHECK: all register lines complete and consistent ✓","DATA CHECK: "&(COUNTIF(Purchase_Register!$BJ$6:$BJ$205,"?*")-COUNTIF(Purchase_Register!$BJ$6:$BJ$205,"OK"))&" register line(s) need correction — see Data Check column") -> DATA CHECK: 1 register line(s) need correction — see Data Check column | Q19: ="PENDING IN-HOUSE: "&(COUNTIF(Purchase_Register!$AX$6:$AX$205,"Pending*")+COUNTIF(Purchase_Register!$AX$6:$AX$205,"Not Started*"))&" open PO line(s), BDT "&TEXT(SUMIFS(Purchase_Register!$AW$6:$AW$205,Purchase_Register!$AY$6:$AY$205,"")/100000,"#,##0.00")&" Lakh | Short closed: "&COUNTIF(Purchase_Register!$AX$6:$AX$205,"Short Closed*") -> PENDING IN-HOUSE: 5 open PO line(s), BDT 101.06 Lakh | Short closed: 7
A21: MANAGEMENT HIGHLIGHTS — written automatically from the latest data
A22: ="▸ Spend: BDT "&TEXT((SUM(Purchase_Register!$AD$6:$AD$205))/100000,"#,##0.00")&" Lakh committed on "&COUNTA(Purchase_Register!$O$6:$O$205)&" POs — "&TEXT(IFERROR(SUM(Purchase_Register!$AI$6:$AI$205)/SUM(Purchase_Register!$AD$6:$AD$205),0),"0%")&" paid; BDT "&TEXT((SUM(Purchase_Register!$AK$6:$AK$205))/100000,"#,##0.00")&" Lakh outstanding, of which BDT "&TEXT((SUMIFS(Purchase_Register!$AK$6:$AK$205,Purchase_Register!$AP$6:$AP$205,">0"))/100000,"#,##0.00")&" Lakh is overdue." -> ▸ Spend: BDT 565.19 Lakh committed on 39 POs — 60% paid; BDT 226.72 Lakh outstanding, of which BDT 33.24 Lakh is overdue.
A23: ="▸ Concentration: largest supplier is "&IFERROR(INDEX(Supplier_Scorecard!$A$5:$A$34,MATCH(MAX(Supplier_Scorecard!$D$5:$D$34),Supplier_Scorecard!$D$5:$D$34,0)),"-")&" with "&TEXT(MAX(Supplier_Scorecard!$D$5:$D$34),"0%")&" of spend — "&LOWER(Supplier_Scorecard!$C$41)&" (HHI "&TEXT(Supplier_Scorecard!$C$40,"#,##0")&"). Top category: "&Spend_Analysis!$B$6&" at "&TEXT(N(Spend_Analysis!$F$6),"0%")&"; "&COUNTIF(Spend_Analysis!$H$6:$H$25,"A")&" A-class categories carry "&TEXT(SUMIF(Spend_Analysis!$H$6:$H$25,"A",Spend_Analysis!$F$6:$F$25),"0%")&" of spend." -> ▸ Concentration: largest supplier is Savar Leather Works Ltd with 32% of spend — moderately concentrated (HHI 1,959). Top category: Leather & Upper at 32%; 4 A-class categories carry 89% of spend.
A24: ="▸ Supplier performance: "&COUNTIF(Supplier_Scorecard!$R$5:$R$34,"A*")&" rated A-Preferred, "&COUNTIF(Supplier_Scorecard!$R$5:$R$34,"B*")&" B-Approved, "&COUNTIF(Supplier_Scorecard!$R$5:$R$34,"C*")&" C-Review. "&IF(COUNT(Supplier_Scorecard!$Q$5:$Q$34)=0,"No supplier scored yet.","Best: "&INDEX(Supplier_Scorecard!$A$5:$A$34,MATCH(MAX(Supplier_Scorecard!$Q$5:$Q$34),Supplier_Scorecard!$Q$5:$Q$34,0))&" ("&MAX(Supplier_Scorecard!$Q$5:$Q$34)&"); weakest: "&INDEX(Supplier_Scorecard!$A$5:$A$34,MATCH(MIN(Supplier_Scorecard!$Q$5:$Q$34),Supplier_Scorecard!$Q$5:$Q$34,0))&" ("&MIN(Supplier_Scorecard!$Q$5:$Q$34)&").") -> ▸ Supplier performance: 3 rated A-Preferred, 4 B-Approved, 3 C-Review. Best: Chattogram Packaging Ltd (100); weakest: Gazipur Chem Trade (51).
A25: ="▸ Delivery: OTIF "&TEXT(IFERROR(COUNTIF(Purchase_Register!$BE$6:$BE$205,"OTIF")/COUNTIF(Purchase_Register!$BE$6:$BE$205,"*OTIF"),0),"0%")&", in-full "&TEXT(IFERROR(COUNTIFS(Purchase_Register!$BE$6:$BE$205,"*OTIF",Purchase_Register!$AX$6:$AX$205,"All In-house*")/COUNTIF(Purchase_Register!$BE$6:$BE$205,"*OTIF"),0),"0%")&", average lead time "&TEXT(IFERROR(AVERAGE(Purchase_Register!$BB$6:$BB$205),0),"0")&" days. "&COUNTIFS(Purchase_Register!$O$6:$O$205,"<>",Purchase_Register!$AY$6:$AY$205,"",Purchase_Register!$BD$6:$BD$205,">0")&" open PO(s) are late; BDT "&TEXT((SUMIFS(Purchase_Register!$AW$6:$AW$205,Purchase_Register!$AY$6:$AY$205,""))/100000,"#,##0.00")&" Lakh of material still to come in-house; "&COUNTIF(Purchase_Register!$AX$6:$AX$205,"Short Closed*")&" line(s) short-closed." -> ▸ Delivery: OTIF 50%, in-full 79%, average lead time 22 days. 0 open PO(s) are late; BDT 101.06 Lakh of material still to come in-house; 7 line(s) short-closed.
A26: ="▸ Budget & price: "&COUNTIF(Budget_Control!$M$5:$M$24,"Over Budget")&" department(s) over budget, "&COUNTIF(Budget_Control!$M$5:$M$24,"Watch")&" on watch (overall "&TEXT(IFERROR(Budget_Control!$I$25/Budget_Control!$H$25,0),"0%")&" used). Buying vs budget price: BDT "&TEXT((-SUMIF(Purchase_Register!$AA$6:$AA$205,"<0"))/100000,"#,##0.00")&" Lakh saved, BDT "&TEXT((SUMIF(Purchase_Register!$AA$6:$AA$205,">0"))/100000,"#,##0.00")&" Lakh overspent; "&COUNTIF(Purchase_Register!$Z$6:$Z$205,">0")&" line(s) bought dearer than the previous PO." -> ▸ Budget & price: 1 department(s) over budget, 1 on watch (overall 44% used). Buying vs budget price: BDT 3.73 Lakh saved, BDT 13.42 Lakh overspent; 6 line(s) bought dearer than the previous PO.
A27: ="▸ Cash & risk: BDT "&TEXT((SUM(Purchase_Register!$AL$6:$AL$205))/100000,"#,##0.00")&" Lakh paid ahead of goods received; "&COUNTIF(Purchase_Register!$BL$6:$BL$205,"High")&" high, "&COUNTIF(Purchase_Register!$BL$6:$BL$205,"Medium")&" medium and "&COUNTIF(Purchase_Register!$BL$6:$BL$205,"Low")&" low priority action line(s) open; "&COUNTIFS(Purchase_Register!$O$6:$O$205,"<>",Purchase_Register!$K$6:$K$205,"<>Approved")&" PO(s) without approval." -> ▸ Cash & risk: BDT 42.79 Lakh paid ahead of goods received; 12 high, 7 medium and 3 low priority action line(s) open; 0 PO(s) without approval.
A139: CHART DATA (auto-calculated — feeds the charts above)
A140: Category | B140: Committed (Lakh) | C140: Paid (Lakh) | D140: Outstanding (Lakh) | F140: Spend Type | G140: Committed (Lakh) | I140: Finance Status | J140: PO Lines | K140: Value (Lakh) | M140: Month | N140: PO Value (Lakh) | O140: Paid (Lakh) | P140: Due (Lakh) | R140: Supplier (top 10 by spend) | S140: Spend (Lakh) | T140: OTIF % | U140: Score
A141: =Spend_Analysis!B6 -> Leather & Upper | B141: =IF($A141="","",SUMIFS(Purchase_Register!$AD$6:$AD$205,Purchase_Register!$F$6:$F$205,$A141)/100000) -> 178.29948 | C141: =IF($A141="","",SUMIFS(Purchase_Register!$AI$6:$AI$205,Purchase_Register!$F$6:$F$205,$A141)/100000) -> 119.63533 | D141: =IF($A141="","",SUMIFS(Purchase_Register!$AK$6:$AK$205,Purchase_Register!$F$6:$F$205,$A141)/100000) -> 58.664154 | F141: OPEX | G141: =SUMIFS(Purchase_Register!$AD$6:$AD$205,Purchase_Register!$H$6:$H$205,$F141)/100000 -> 439.64954 | I141: Not Paid | J141: =COUNTIF(Purchase_Register!$AM$6:$AM$205,$I141) -> 5 | K141: =SUMIFS(Purchase_Register!$AD$6:$AD$205,Purchase_Register!$AM$6:$AM$205,$I141)/100000 -> 44.915228 | M141: =Cash_Forecast!C5 -> Jul-26 | N141: =Cash_Forecast!F5/100000 -> 49.330286 | O141: =Cash_Forecast!I5/100000 -> 33.576362 | P141: =Cash_Forecast!J5/100000 -> 0 | R141: =INDEX(Supplier_Scorecard!$A$5:$A$34,MATCH(LARGE(Supplier_Scorecard!$S$5:$S$34,1),Supplier_Scorecard!$S$5:$S$34,0))&"" -> Savar Leather Works Ltd | S141: =IF($R141="","",N(INDEX(Supplier_Scorecard!$C$5:$C$34,MATCH(LARGE(Supplier_Scorecard!$S$5:$S$34,1),Supplier_Scorecard!$S$5:$S$34,0)))/100000) -> 178.29948 | T141: =IF($R141="","",INDEX(Supplier_Scorecard!$H$5:$H$34,MATCH(LARGE(Supplier_Scorecard!$S$5:$S$34,1),Supplier_Scorecard!$S$5:$S$34,0))) -> 0.6 | U141: =IF($R141="","",INDEX(Supplier_Scorecard!$Q$5:$Q$34,MATCH(LARGE(Supplier_Scorecard!$S$5:$S$34,1),Supplier_Scorecard!$S$5:$S$34,0))) -> 66
A142: =Spend_Analysis!B7 -> Machinery & Equipment | B142: =IF($A142="","",SUMIFS(Purchase_Register!$AD$6:$AD$205,Purchase_Register!$F$6:$F$205,$A142)/100000) -> 117.92226 | C142: =IF($A142="","",SUMIFS(Purchase_Register!$AI$6:$AI$205,Purchase_Register!$F$6:$F$205,$A142)/100000) -> 66.998694 | D142: =IF($A142="","",SUMIFS(Purchase_Register!$AK$6:$AK$205,Purchase_Register!$F$6:$F$205,$A142)/100000) -> 50.923564 | F142: CAPEX | G142: =SUMIFS(Purchase_Register!$AD$6:$AD$205,Purchase_Register!$H$6:$H$205,$F142)/100000 -> 125.54046 | I142: Initial / Advance Paid | J142: =COUNTIF(Purchase_Register!$AM$6:$AM$205,$I142) -> 9 | K142: =SUMIFS(Purchase_Register!$AD$6:$AD$205,Purchase_Register!$AM$6:$AM$205,$I142)/100000 -> 182.63263 | M142: =Cash_Forecast!C6 -> Aug-26 | N142: =Cash_Forecast!F6/100000 -> 165.19154 | O142: =Cash_Forecast!I6/100000 -> 116.03703 | P142: =Cash_Forecast!J6/100000 -> 14.83293 | R142: =INDEX(Supplier_Scorecard!$A$5:$A$34,MATCH(LARGE(Supplier_Scorecard!$S$5:$S$34,2),Supplier_Scorecard!$S$5:$S$34,0))&"" -> Dongguan Sole Tech Co. | S142: =IF($R142="","",N(INDEX(Supplier_Scorecard!$C$5:$C$34,MATCH(LARGE(Supplier_Scorecard!$S$5:$S$34,2),Supplier_Scorecard!$S$5:$S$34,0)))/100000) -> 105.89897 | T142: =IF($R142="","",INDEX(Supplier_Scorecard!$H$5:$H$34,MATCH(LARGE(Supplier_Scorecard!$S$5:$S$34,2),Supplier_Scorecard!$S$5:$S$34,0))) -> 1 | U142: =IF($R142="","",INDEX(Supplier_Scorecard!$Q$5:$Q$34,MATCH(LARGE(Supplier_Scorecard!$S$5:$S$34,2),Supplier_Scorecard!$S$5:$S$34,0))) -> 98
A143: =Spend_Analysis!B8 -> Sole & Bottom | B143: =IF($A143="","",SUMIFS(Purchase_Register!$AD$6:$AD$205,Purchase_Register!$F$6:$F$205,$A143)/100000) -> 103.98765 | C143: =IF($A143="","",SUMIFS(Purchase_Register!$AI$6:$AI$205,Purchase_Register!$F$6:$F$205,$A143)/100000) -> 35.31309 | D143: =IF($A143="","",SUMIFS(Purchase_Register!$AK$6:$AK$205,Purchase_Register!$F$6:$F$205,$A143)/100000) -> 68.674562 | I143: Partially Paid | J143: =COUNTIF(Purchase_Register!$AM$6:$AM$205,$I143) -> 5 | K143: =SUMIFS(Purchase_Register!$AD$6:$AD$205,Purchase_Register!$AM$6:$AM$205,$I143)/100000 -> 33.66531 | M143: =Cash_Forecast!C7 -> Sep-26 | N143: =Cash_Forecast!F7/100000 -> 95.140112 | O143: =Cash_Forecast!I7/100000 -> 93.218794 | P143: =Cash_Forecast!J7/100000 -> 16.955387 | R143: =INDEX(Supplier_Scorecard!$A$5:$A$34,MATCH(LARGE(Supplier_Scorecard!$S$5:$S$34,3),Supplier_Scorecard!$S$5:$S$34,0))&"" -> Jiangsu Footwear Machinery Co. | S143: =IF($R143="","",N(INDEX(Supplier_Scorecard!$C$5:$C$34,MATCH(LARGE(Supplier_Scorecard!$S$5:$S$34,3),Supplier_Scorecard!$S$5:$S$34,0)))/100000) -> 101.84713 | T143: =IF($R143="","",INDEX(Supplier_Scorecard!$H$5:$H$34,MATCH(LARGE(Supplier_Scorecard!$S$5:$S$34,3),Supplier_Scorecard!$S$5:$S$34,0))) -> 0 | U143: =IF($R143="","",INDEX(Supplier_Scorecard!$Q$5:$Q$34,MATCH(LARGE(Supplier_Scorecard!$S$5:$S$34,3),Supplier_Scorecard!$S$5:$S$34,0))) -> 53
A144: =Spend_Analysis!B9 -> Synthetic & Textile | B144: =IF($A144="","",SUMIFS(Purchase_Register!$AD$6:$AD$205,Purchase_Register!$F$6:$F$205,$A144)/100000) -> 101.05757 | C144: =IF($A144="","",SUMIFS(Purchase_Register!$AI$6:$AI$205,Purchase_Register!$F$6:$F$205,$A144)/100000) -> 81.013451 | D144: =IF($A144="","",SUMIFS(Purchase_Register!$AK$6:$AK$205,Purchase_Register!$F$6:$F$205,$A144)/100000) -> 20.044116 | F144: Stage | G144: Lines | I144: Fully Paid | J144: =COUNTIF(Purchase_Register!$AM$6:$AM$205,$I144) -> 20 | K144: =SUMIFS(Purchase_Register!$AD$6:$AD$205,Purchase_Register!$AM$6:$AM$205,$I144)/100000 -> 244.95765 | M144: =Cash_Forecast!C8 -> Oct-26 | N144: =Cash_Forecast!F8/100000 -> 68.928231 | O144: =Cash_Forecast!I8/100000 -> 39.865209 | P144: =Cash_Forecast!J8/100000 -> 63.374494 | R144: =INDEX(Supplier_Scorecard!$A$5:$A$34,MATCH(LARGE(Supplier_Scorecard!$S$5:$S$34,4),Supplier_Scorecard!$S$5:$S$34,0))&"" -> Bengal Sole Industries | S144: =IF($R144="","",N(INDEX(Supplier_Scorecard!$C$5:$C$34,MATCH(LARGE(Supplier_Scorecard!$S$5:$S$34,4),Supplier_Scorecard!$S$5:$S$34,0)))/100000) -> 86.46225 | T144: =IF($R144="","",INDEX(Supplier_Scorecard!$H$5:$H$34,MATCH(LARGE(Supplier_Scorecard!$S$5:$S$34,4),Supplier_Scorecard!$S$5:$S$34,0))) -> 0.5 | U144: =IF($R144="","",INDEX(Supplier_Scorecard!$Q$5:$Q$34,MATCH(LARGE(Supplier_Scorecard!$S$5:$S$34,4),Supplier_Scorecard!$S$5:$S$34,0))) -> 64
A145: =Spend_Analysis!B10 -> Chemicals & Adhesives | B145: =IF($A145="","",SUMIFS(Purchase_Register!$AD$6:$AD$205,Purchase_Register!$F$6:$F$205,$A145)/100000) -> 23.8392 | C145: =IF($A145="","",SUMIFS(Purchase_Register!$AI$6:$AI$205,Purchase_Register!$F$6:$F$205,$A145)/100000) -> 9.355725 | D145: =IF($A145="","",SUMIFS(Purchase_Register!$AK$6:$AK$205,Purchase_Register!$F$6:$F$205,$A145)/100000) -> 14.483475 | F145: Awaiting Approval | G145: =COUNTIF(Purchase_Register!$BI$6:$BI$205,$F145) -> 3 | M145: =Cash_Forecast!C9 -> Nov-26 | N145: =Cash_Forecast!F9/100000 -> 0 | O145: =Cash_Forecast!I9/100000 -> 0 | P145: =Cash_Forecast!J9/100000 -> 72.534849 | R145: =INDEX(Supplier_Scorecard!$A$5:$A$34,MATCH(LARGE(Supplier_Scorecard!$S$5:$S$34,5),Supplier_Scorecard!$S$5:$S$34,0))&"" -> Dhaka Spares & Tools | S145: =IF($R145="","",N(INDEX(Supplier_Scorecard!$C$5:$C$34,MATCH(LARGE(Supplier_Scorecard!$S$5:$S$34,5),Supplier_Scorecard!$S$5:$S$34,0)))/100000) -> 25.885323 | T145: =IF($R145="","",INDEX(Supplier_Scorecard!$H$5:$H$34,MATCH(LARGE(Supplier_Scorecard!$S$5:$S$34,5),Supplier_Scorecard!$S$5:$S$34,0))) -> 0.33333333 | U145: =IF($R145="","",INDEX(Supplier_Scorecard!$Q$5:$Q$34,MATCH(LARGE(Supplier_Scorecard!$S$5:$S$34,5),Supplier_Scorecard!$S$5:$S$34,0))) -> 65
A146: =Spend_Analysis!B11 -> Trims & Accessories | B146: =IF($A146="","",SUMIFS(Purchase_Register!$AD$6:$AD$205,Purchase_Register!$F$6:$F$205,$A146)/100000) -> 13.310388 | C146: =IF($A146="","",SUMIFS(Purchase_Register!$AI$6:$AI$205,Purchase_Register!$F$6:$F$205,$A146)/100000) -> 7.286202 | D146: =IF($A146="","",SUMIFS(Purchase_Register!$AK$6:$AK$205,Purchase_Register!$F$6:$F$205,$A146)/100000) -> 6.024186 | F146: Approved - PO Pending | G146: =COUNTIF(Purchase_Register!$BI$6:$BI$205,$F146) -> 2 | I146: Aging Bucket | J146: Outstanding (Lakh) | M146: =Cash_Forecast!C10 -> Dec-26 | N146: =Cash_Forecast!F10/100000 -> 0 | O146: =Cash_Forecast!I10/100000 -> 0 | P146: =Cash_Forecast!J10/100000 -> 0 | R146: =INDEX(Supplier_Scorecard!$A$5:$A$34,MATCH(LARGE(Supplier_Scorecard!$S$5:$S$34,6),Supplier_Scorecard!$S$5:$S$34,0))&"" -> Gazipur Chem Trade | S146: =IF($R146="","",N(INDEX(Supplier_Scorecard!$C$5:$C$34,MATCH(LARGE(Supplier_Scorecard!$S$5:$S$34,6),Supplier_Scorecard!$S$5:$S$34,0)))/100000) -> 23.8392 | T146: =IF($R146="","",INDEX(Supplier_Scorecard!$H$5:$H$34,MATCH(LARGE(Supplier_Scorecard!$S$5:$S$34,6),Supplier_Scorecard!$S$5:$S$34,0))) -> 0.5 | U146: =IF($R146="","",INDEX(Supplier_Scorecard!$Q$5:$Q$34,MATCH(LARGE(Supplier_Scorecard!$S$5:$S$34,6),Supplier_Scorecard!$S$5:$S$34,0))) -> 51
A147: =Spend_Analysis!B12 -> Packaging | B147: =IF($A147="","",SUMIFS(Purchase_Register!$AD$6:$AD$205,Purchase_Register!$F$6:$F$205,$A147)/100000) -> 9.345063 | C147: =IF($A147="","",SUMIFS(Purchase_Register!$AI$6:$AI$205,Purchase_Register!$F$6:$F$205,$A147)/100000) -> 9.345063 | D147: =IF($A147="","",SUMIFS(Purchase_Register!$AK$6:$AK$205,Purchase_Register!$F$6:$F$205,$A147)/100000) -> 0 | F147: PO Issued - Awaiting Delivery | G147: =COUNTIF(Purchase_Register!$BI$6:$BI$205,$F147) -> 4 | I147: Not Yet Due | J147: =SUMIFS(Purchase_Register!$AK$6:$AK$205,Purchase_Register!$AQ$6:$AQ$205,$I147)/100000 -> 134.46003 | M147: =Cash_Forecast!C11 -> Jan-27 | N147: =Cash_Forecast!F11/100000 -> 0 | O147: =Cash_Forecast!I11/100000 -> 0 | P147: =Cash_Forecast!J11/100000 -> 0 | R147: =INDEX(Supplier_Scorecard!$A$5:$A$34,MATCH(LARGE(Supplier_Scorecard!$S$5:$S$34,7),Supplier_Scorecard!$S$5:$S$34,0))&"" -> Delta Thread & Trims | S147: =IF($R147="","",N(INDEX(Supplier_Scorecard!$C$5:$C$34,MATCH(LARGE(Supplier_Scorecard!$S$5:$S$34,7),Supplier_Scorecard!$S$5:$S$34,0)))/100000) -> 13.310388 | T147: =IF($R147="","",INDEX(Supplier_Scorecard!$H$5:$H$34,MATCH(LARGE(Supplier_Scorecard!$S$5:$S$34,7),Supplier_Scorecard!$S$5:$S$34,0))) -> 0.4 | U147: =IF($R147="","",INDEX(Supplier_Scorecard!$Q$5:$Q$34,MATCH(LARGE(Supplier_Scorecard!$S$5:$S$34,7),Supplier_Scorecard!$S$5:$S$34,0))) -> 65
A148: =Spend_Analysis!B13 -> IT Equipment | B148: =IF($A148="","",SUMIFS(Purchase_Register!$AD$6:$AD$205,Purchase_Register!$F$6:$F$205,$A148)/100000) -> 7.6182015 | C148: =IF($A148="","",SUMIFS(Purchase_Register!$AI$6:$AI$205,Purchase_Register!$F$6:$F$205,$A148)/100000) -> 3.8091008 | D148: =IF($A148="","",SUMIFS(Purchase_Register!$AK$6:$AK$205,Purchase_Register!$F$6:$F$205,$A148)/100000) -> 3.8091007 | F148: Receiving In-house | G148: =COUNTIF(Purchase_Register!$BI$6:$BI$205,$F148) -> 1 | I148: 1-30 Days | J148: =SUMIFS(Purchase_Register!$AK$6:$AK$205,Purchase_Register!$AQ$6:$AQ$205,$I148)/100000 -> 13.802777 | M148: =Cash_Forecast!C12 -> Feb-27 | N148: =Cash_Forecast!F12/100000 -> 0 | O148: =Cash_Forecast!I12/100000 -> 0 | P148: =Cash_Forecast!J12/100000 -> 0 | R148: =INDEX(Supplier_Scorecard!$A$5:$A$34,MATCH(LARGE(Supplier_Scorecard!$S$5:$S$34,8),Supplier_Scorecard!$S$5:$S$34,0))&"" -> Narayanganj Board Mills | S148: =IF($R148="","",N(INDEX(Supplier_Scorecard!$C$5:$C$34,MATCH(LARGE(Supplier_Scorecard!$S$5:$S$34,8),Supplier_Scorecard!$S$5:$S$34,0)))/100000) -> 12.684 | T148: =IF($R148="","",INDEX(Supplier_Scorecard!$H$5:$H$34,MATCH(LARGE(Supplier_Scorecard!$S$5:$S$34,8),Supplier_Scorecard!$S$5:$S$34,0))) -> 0 | U148: =IF($R148="","",INDEX(Supplier_Scorecard!$Q$5:$Q$34,MATCH(LARGE(Supplier_Scorecard!$S$5:$S$34,8),Supplier_Scorecard!$S$5:$S$34,0))) -> 59
A149: =Spend_Analysis!B14 -> Safety & Facility | B149: =IF($A149="","",SUMIFS(Purchase_Register!$AD$6:$AD$205,Purchase_Register!$F$6:$F$205,$A149)/100000) -> 6.18125 | C149: =IF($A149="","",SUMIFS(Purchase_Register!$AI$6:$AI$205,Purchase_Register!$F$6:$F$205,$A149)/100000) -> 3.65801 | D149: =IF($A149="","",SUMIFS(Purchase_Register!$AK$6:$AK$205,Purchase_Register!$F$6:$F$205,$A149)/100000) -> 2.52324 | F149: In-house Closed - Payment Due | G149: =COUNTIF(Purchase_Register!$BI$6:$BI$205,$F149) -> 16 | I149: 31-60 Days | J149: =SUMIFS(Purchase_Register!$AK$6:$AK$205,Purchase_Register!$AQ$6:$AQ$205,$I149)/100000 -> 5.688675 | M149: =Cash_Forecast!C13 -> Mar-27 | N149: =Cash_Forecast!F13/100000 -> 0 | O149: =Cash_Forecast!I13/100000 -> 0 | P149: =Cash_Forecast!J13/100000 -> 0 | R149: =INDEX(Supplier_Scorecard!$A$5:$A$34,MATCH(LARGE(Supplier_Scorecard!$S$5:$S$34,9),Supplier_Scorecard!$S$5:$S$34,0))&"" -> Chattogram Packaging Ltd | S149: =IF($R149="","",N(INDEX(Supplier_Scorecard!$C$5:$C$34,MATCH(LARGE(Supplier_Scorecard!$S$5:$S$34,9),Supplier_Scorecard!$S$5:$S$34,0)))/100000) -> 9.345063 | T149: =IF($R149="","",INDEX(Supplier_Scorecard!$H$5:$H$34,MATCH(LARGE(Supplier_Scorecard!$S$5:$S$34,9),Supplier_Scorecard!$S$5:$S$34,0))) -> 1 | U149: =IF($R149="","",INDEX(Supplier_Scorecard!$Q$5:$Q$34,MATCH(LARGE(Supplier_Scorecard!$S$5:$S$34,9),Supplier_Scorecard!$S$5:$S$34,0))) -> 100
A150: =Spend_Analysis!B15 -> Spare Parts | B150: =IF($A150="","",SUMIFS(Purchase_Register!$AD$6:$AD$205,Purchase_Register!$F$6:$F$205,$A150)/100000) -> 3.628942 | C150: =IF($A150="","",SUMIFS(Purchase_Register!$AI$6:$AI$205,Purchase_Register!$F$6:$F$205,$A150)/100000) -> 2.058496 | D150: =IF($A150="","",SUMIFS(Purchase_Register!$AK$6:$AK$205,Purchase_Register!$F$6:$F$205,$A150)/100000) -> 1.570446 | F150: Closed | G150: =COUNTIF(Purchase_Register!$BI$6:$BI$205,$F150) -> 18 | I150: 61-90 Days | J150: =SUMIFS(Purchase_Register!$AK$6:$AK$205,Purchase_Register!$AQ$6:$AQ$205,$I150)/100000 -> 13.74618 | M150: =Cash_Forecast!C14 -> Apr-27 | N150: =Cash_Forecast!F14/100000 -> 0 | O150: =Cash_Forecast!I14/100000 -> 0 | P150: =Cash_Forecast!J14/100000 -> 0 | R150: =INDEX(Supplier_Scorecard!$A$5:$A$34,MATCH(LARGE(Supplier_Scorecard!$S$5:$S$34,10),Supplier_Scorecard!$S$5:$S$34,0))&"" -> Tech Point BD | S150: =IF($R150="","",N(INDEX(Supplier_Scorecard!$C$5:$C$34,MATCH(LARGE(Supplier_Scorecard!$S$5:$S$34,10),Supplier_Scorecard!$S$5:$S$34,0)))/100000) -> 7.6182015 | T150: =IF($R150="","",INDEX(Supplier_Scorecard!$H$5:$H$34,MATCH(LARGE(Supplier_Scorecard!$S$5:$S$34,10),Supplier_Scorecard!$S$5:$S$34,0))) -> 1 | U150: =IF($R150="","",INDEX(Supplier_Scorecard!$Q$5:$Q$34,MATCH(LARGE(Supplier_Scorecard!$S$5:$S$34,10),Supplier_Scorecard!$S$5:$S$34,0))) -> 88
F151: Rejected | G151: =COUNTIF(Purchase_Register!$BI$6:$BI$205,$F151) -> 1 | I151: 90+ Days | J151: =SUMIFS(Purchase_Register!$AK$6:$AK$205,Purchase_Register!$AQ$6:$AQ$205,$I151)/100000 -> 0 | M151: =Cash_Forecast!C15 -> May-27 | N151: =Cash_Forecast!F15/100000 -> 0 | O151: =Cash_Forecast!I15/100000 -> 0 | P151: =Cash_Forecast!J15/100000 -> 0
I152: No Due Date | J152: =SUMIFS(Purchase_Register!$AK$6:$AK$205,Purchase_Register!$AQ$6:$AQ$205,$I152)/100000 -> 59.019183 | M152: =Cash_Forecast!C16 -> Jun-27 | N152: =Cash_Forecast!F16/100000 -> 0 | O152: =Cash_Forecast!I16/100000 -> 0 | P152: =Cash_Forecast!J16/100000 -> 0
M153: Department | N153: Budget (Lakh) | O153: Committed (Lakh) | P153: Utilisation
M154: =INDEX(Budget_Control!$A$5:$A$24,MATCH(LARGE(Budget_Control!$N$5:$N$24,1),Budget_Control!$N$5:$N$24,0))&"" -> Lasting & Assembly | N154: =IF($M154="","",N(INDEX(Budget_Control!$H$5:$H$24,MATCH(LARGE(Budget_Control!$N$5:$N$24,1),Budget_Control!$N$5:$N$24,0)))/100000) -> 340 | O154: =IF($M154="","",N(INDEX(Budget_Control!$I$5:$I$24,MATCH(LARGE(Budget_Control!$N$5:$N$24,1),Budget_Control!$N$5:$N$24,0)))/100000) -> 100.69343 | P154: =IF(OR($M154="",N(N154)=0),"",O154/N154) -> 0.29615714
M155: =INDEX(Budget_Control!$A$5:$A$24,MATCH(LARGE(Budget_Control!$N$5:$N$24,2),Budget_Control!$N$5:$N$24,0))&"" -> Cutting | N155: =IF($M155="","",N(INDEX(Budget_Control!$H$5:$H$24,MATCH(LARGE(Budget_Control!$N$5:$N$24,2),Budget_Control!$N$5:$N$24,0)))/100000) -> 320 | O155: =IF($M155="","",N(INDEX(Budget_Control!$I$5:$I$24,MATCH(LARGE(Budget_Control!$N$5:$N$24,2),Budget_Control!$N$5:$N$24,0)))/100000) -> 279.35705 | P155: =IF(OR($M155="",N(N155)=0),"",O155/N155) -> 0.87299078
M156: =INDEX(Budget_Control!$A$5:$A$24,MATCH(LARGE(Budget_Control!$N$5:$N$24,3),Budget_Control!$N$5:$N$24,0))&"" -> Stitching | N156: =IF($M156="","",N(INDEX(Budget_Control!$H$5:$H$24,MATCH(LARGE(Budget_Control!$N$5:$N$24,3),Budget_Control!$N$5:$N$24,0)))/100000) -> 150 | O156: =IF($M156="","",N(INDEX(Budget_Control!$I$5:$I$24,MATCH(LARGE(Budget_Control!$N$5:$N$24,3),Budget_Control!$N$5:$N$24,0)))/100000) -> 13.310388 | P156: =IF(OR($M156="",N(N156)=0),"",O156/N156) -> 0.08873592
M157: =INDEX(Budget_Control!$A$5:$A$24,MATCH(LARGE(Budget_Control!$N$5:$N$24,4),Budget_Control!$N$5:$N$24,0))&"" -> Finishing & Packing | N157: =IF($M157="","",N(INDEX(Budget_Control!$H$5:$H$24,MATCH(LARGE(Budget_Control!$N$5:$N$24,4),Budget_Control!$N$5:$N$24,0)))/100000) -> 140 | O157: =IF($M157="","",N(INDEX(Budget_Control!$I$5:$I$24,MATCH(LARGE(Budget_Control!$N$5:$N$24,4),Budget_Control!$N$5:$N$24,0)))/100000) -> 9.345063 | P157: =IF(OR($M157="",N(N157)=0),"",O157/N157) -> 0.06675045
M158: =INDEX(Budget_Control!$A$5:$A$24,MATCH(LARGE(Budget_Control!$N$5:$N$24,5),Budget_Control!$N$5:$N$24,0))&"" -> Maintenance | N158: =IF($M158="","",N(INDEX(Budget_Control!$H$5:$H$24,MATCH(LARGE(Budget_Control!$N$5:$N$24,5),Budget_Control!$N$5:$N$24,0)))/100000) -> 100 | O158: =IF($M158="","",N(INDEX(Budget_Control!$I$5:$I$24,MATCH(LARGE(Budget_Control!$N$5:$N$24,5),Budget_Control!$N$5:$N$24,0)))/100000) -> 120.38323 | P158: =IF(OR($M158="",N(N158)=0),"",O158/N158) -> 1.2038323
...

Sheet Action_Tracker
A1: Action Tracker — what needs attention today
A2: Automatic list from the Purchase Register, sorted High → Medium → Low priority. Fix the cause in the register and the line drops off this list.
C3: High priority | E3: Medium priority | F3: Low priority | G3: Overdue payable (BDT) | I3: Paid ahead of receipt (BDT) | J3: Late open POs
C4: =COUNTIF(Purchase_Register!$BL$6:$BL$205,"High") -> 12 | E4: =COUNTIF(Purchase_Register!$BL$6:$BL$205,"Medium") -> 7 | F4: =COUNTIF(Purchase_Register!$BL$6:$BL$205,"Low") -> 3 | G4: =SUMIFS(Purchase_Register!$AK$6:$AK$205,Purchase_Register!$AP$6:$AP$205,">0") -> 3323763.2 | I4: =SUM(Purchase_Register!$AL$6:$AL$205) -> 4278510 | J4: =COUNTIFS(Purchase_Register!$O$6:$O$205,"<>",Purchase_Register!$AY$6:$AY$205,"",Purchase_Register!$BD$6:$BD$205,">0") -> 0
A6: # | B6: Reg. row | C6: Priority | D6: PR No | E6: Item / Material | F6: Supplier | G6: Department | H6: Current Stage | I6: Pending Material Status | J6: Outstanding Payable (BDT) | K6: Paid Ahead of Receipt (BDT) | L6: Action Required
A7: =IF(ROWS($A$7:A7)>COUNT(Purchase_Register!$BM$6:$BM$205),"",ROWS($A$7:A7)) -> 1 | B7: =IF($A7="","",MATCH(SMALL(Purchase_Register!$BM$6:$BM$205,$A7),Purchase_Register!$BM$6:$BM$205,0)) -> 2 | C7: =IF($B7="","",INDEX(Purchase_Register!$BL$6:$BL$205,$B7)&"") -> High | D7: =IF($B7="","",INDEX(Purchase_Register!$A$6:$A$205,$B7)&"") -> PSIL-PR-2026-0002 | E7: =IF($B7="","",INDEX(Purchase_Register!$E$6:$E$205,$B7)&"") -> Suede Split Leather | F7: =IF($B7="","",INDEX(Purchase_Register!$M$6:$M$205,$B7)&"") -> Savar Leather Works Ltd | G7: =IF($B7="","",INDEX(Purchase_Register!$C$6:$C$205,$B7)&"") -> Cutting | H7: =IF($B7="","",INDEX(Purchase_Register!$BI$6:$BI$205,$B7)&"") -> Closed | I7: =IF($B7="","",INDEX(Purchase_Register!$AX$6:$AX$205,$B7)&"") -> All In-house | J7: =IF($B7="","",N(INDEX(Purchase_Register!$AK$6:$AK$205,$B7))) -> 0 | K7: =IF($B7="","",N(INDEX(Purchase_Register!$AL$6:$AL$205,$B7))) -> 0 | L7: =IF($B7="","",INDEX(Purchase_Register!$BK$6:$BK$205,$B7)&"") -> QC rejected: return / replace;
A8: =IF(ROWS($A$7:A8)>COUNT(Purchase_Register!$BM$6:$BM$205),"",ROWS($A$7:A8)) -> 2 | B8: =IF($A8="","",MATCH(SMALL(Purchase_Register!$BM$6:$BM$205,$A8),Purchase_Register!$BM$6:$BM$205,0)) -> 5 | C8: =IF($B8="","",INDEX(Purchase_Register!$BL$6:$BL$205,$B8)&"") -> High | D8: =IF($B8="","",INDEX(Purchase_Register!$A$6:$A$205,$B8)&"") -> PSIL-PR-2026-0005 | E8: =IF($B8="","",INDEX(Purchase_Register!$E$6:$E$205,$B8)&"") -> Rubber Outsole – Men's Derby | F8: =IF($B8="","",INDEX(Purchase_Register!$M$6:$M$205,$B8)&"") -> Bengal Sole Industries | G8: =IF($B8="","",INDEX(Purchase_Register!$C$6:$C$205,$B8)&"") -> Lasting & Assembly | H8: =IF($B8="","",INDEX(Purchase_Register!$BI$6:$BI$205,$B8)&"") -> In-house Closed - Payment Due | I8: =IF($B8="","",INDEX(Purchase_Register!$AX$6:$AX$205,$B8)&"") -> Short Closed - 561 pair not received | J8: =IF($B8="","",N(INDEX(Purchase_Register!$AK$6:$AK$205,$B8))) -> 1074150 | K8: =IF($B8="","",N(INDEX(Purchase_Register!$AL$6:$AL$205,$B8))) -> 0 | L8: =IF($B8="","",INDEX(Purchase_Register!$BK$6:$BK$205,$B8)&"") -> Pay supplier: 71 days overdue; Short closed: claim balance / credit note;
A9: =IF(ROWS($A$7:A9)>COUNT(Purchase_Register!$BM$6:$BM$205),"",ROWS($A$7:A9)) -> 3 | B9: =IF($A9="","",MATCH(SMALL(Purchase_Register!$BM$6:$BM$205,$A9),Purchase_Register!$BM$6:$BM$205,0)) -> 8 | C9: =IF($B9="","",INDEX(Purchase_Register!$BL$6:$BL$205,$B9)&"") -> High | D9: =IF($B9="","",INDEX(Purchase_Register!$A$6:$A$205,$B9)&"") -> PSIL-PR-2026-0008 | E9: =IF($B9="","",INDEX(Purchase_Register!$E$6:$E$205,$B9)&"") -> PU Adhesive (Solvent Based) | F9: =IF($B9="","",INDEX(Purchase_Register!$M$6:$M$205,$B9)&"") -> Gazipur Chem Trade | G9: =IF($B9="","",INDEX(Purchase_Register!$C$6:$C$205,$B9)&"") -> Lasting & Assembly | H9: =IF($B9="","",INDEX(Purchase_Register!$BI$6:$BI$205,$B9)&"") -> Closed | I9: =IF($B9="","",INDEX(Purchase_Register!$AX$6:$AX$205,$B9)&"") -> Short Closed - 36 kg not received | J9: =IF($B9="","",N(INDEX(Purchase_Register!$AK$6:$AK$205,$B9))) -> 0 | K9: =IF($B9="","",N(INDEX(Purchase_Register!$AL$6:$AL$205,$B9))) -> 16680 | L9: =IF($B9="","",INDEX(Purchase_Register!$BK$6:$BK$205,$B9)&"") -> Short closed: claim balance / credit note BDT 16,680; QC rejected: return / replace;
A10: =IF(ROWS($A$7:A10)>COUNT(Purchase_Register!$BM$6:$BM$205),"",ROWS($A$7:A10)) -> 4 | B10: =IF($A10="","",MATCH(SMALL(Purchase_Register!$BM$6:$BM$205,$A10),Purchase_Register!$BM$6:$BM$205,0)) -> 10 | C10: =IF($B10="","",INDEX(Purchase_Register!$BL$6:$BL$205,$B10)&"") -> High | D10: =IF($B10="","",INDEX(Purchase_Register!$A$6:$A$205,$B10)&"") -> PSIL-PR-2026-0010 | E10: =IF($B10="","",INDEX(Purchase_Register!$E$6:$E$205,$B10)&"") -> Bonded Nylon Thread | F10: =IF($B10="","",INDEX(Purchase_Register!$M$6:$M$205,$B10)&"") -> Delta Thread & Trims | G10: =IF($B10="","",INDEX(Purchase_Register!$C$6:$C$205,$B10)&"") -> Stitching | H10: =IF($B10="","",INDEX(Purchase_Register!$BI$6:$BI$205,$B10)&"") -> In-house Closed - Payment Due | I10: =IF($B10="","",INDEX(Purchase_Register!$AX$6:$AX$205,$B10)&"") -> Short Closed - 49 cone not received | J10: =IF($B10="","",N(INDEX(Purchase_Register!$AK$6:$AK$205,$B10))) -> 300468 | K10: =IF($B10="","",N(INDEX(Purchase_Register!$AL$6:$AL$205,$B10))) -> 0 | L10: =IF($B10="","",INDEX(Purchase_Register!$BK$6:$BK$205,$B10)&"") -> Pay supplier: 70 days overdue; Short closed: claim balance / credit note;
A11: =IF(ROWS($A$7:A11)>COUNT(Purchase_Register!$BM$6:$BM$205),"",ROWS($A$7:A11)) -> 5 | B11: =IF($A11="","",MATCH(SMALL(Purchase_Register!$BM$6:$BM$205,$A11),Purchase_Register!$BM$6:$BM$205,0)) -> 11 | C11: =IF($B11="","",INDEX(Purchase_Register!$BL$6:$BL$205,$B11)&"") -> High | D11: =IF($B11="","",INDEX(Purchase_Register!$A$6:$A$205,$B11)&"") -> PSIL-PR-2026-0011 | E11: =IF($B11="","",INDEX(Purchase_Register!$E$6:$E$205,$B11)&"") -> Metal Eyelets & Hooks | F11: =IF($B11="","",INDEX(Purchase_Register!$M$6:$M$205,$B11)&"") -> Delta Thread & Trims | G11: =IF($B11="","",INDEX(Purchase_Register!$C$6:$C$205,$B11)&"") -> Stitching | H11: =IF($B11="","",INDEX(Purchase_Register!$BI$6:$BI$205,$B11)&"") -> In-house Closed - Payment Due | I11: =IF($B11="","",INDEX(Purchase_Register!$AX$6:$AX$205,$B11)&"") -> All In-house | J11: =IF($B11="","",N(INDEX(Purchase_Register!$AK$6:$AK$205,$B11))) -> 108675 | K11: =IF($B11="","",N(INDEX(Purchase_Register!$AL$6:$AL$205,$B11))) -> 0 | L11: =IF($B11="","",INDEX(Purchase_Register!$BK$6:$BK$205,$B11)&"") -> Pay supplier: 54 days overdue;
A12: =IF(ROWS($A$7:A12)>COUNT(Purchase_Register!$BM$6:$BM$205),"",ROWS($A$7:A12)) -> 6 | B12: =IF($A12="","",MATCH(SMALL(Purchase_Register!$BM$6:$BM$205,$A12),Purchase_Register!$BM$6:$BM$205,0)) -> 12 | C12: =IF($B12="","",INDEX(Purchase_Register!$BL$6:$BL$205,$B12)&"") -> High | D12: =IF($B12="","",INDEX(Purchase_Register!$A$6:$A$205,$B12)&"") -> PSIL-PR-2026-0012 | E12: =IF($B12="","",INDEX(Purchase_Register!$E$6:$E$205,$B12)&"") -> Waxed Cotton Laces | F12: =IF($B12="","",INDEX(Purchase_Register!$M$6:$M$205,$B12)&"") -> Delta Thread & Trims | G12: =IF($B12="","",INDEX(Purchase_Register!$C$6:$C$205,$B12)&"") -> Stitching | H12: =IF($B12="","",INDEX(Purchase_Register!$BI$6:$BI$205,$B12)&"") -> Closed | I12: =IF($B12="","",INDEX(Purchase_Register!$AX$6:$AX$205,$B12)&"") -> All In-house | J12: =IF($B12="","",N(INDEX(Purchase_Register!$AK$6:$AK$205,$B12))) -> 0 | K12: =IF($B12="","",N(INDEX(Purchase_Register!$AL$6:$AL$205,$B12))) -> 0 | L12: =IF($B12="","",INDEX(Purchase_Register!$BK$6:$BK$205,$B12)&"") -> QC rejected: return / replace;
A13: =IF(ROWS($A$7:A13)>COUNT(Purchase_Register!$BM$6:$BM$205),"",ROWS($A$7:A13)) -> 7 | B13: =IF($A13="","",MATCH(SMALL(Purchase_Register!$BM$6:$BM$205,$A13),Purchase_Register!$BM$6:$BM$205,0)) -> 13 | C13: =IF($B13="","",INDEX(Purchase_Register!$BL$6:$BL$205,$B13)&"") -> High | D13: =IF($B13="","",INDEX(Purchase_Register!$A$6:$A$205,$B13)&"") -> PSIL-PR-2026-0013 | E13: =IF($B13="","",INDEX(Purchase_Register!$E$6:$E$205,$B13)&"") -> Cellulose Insole Board | F13: =IF($B13="","",INDEX(Purchase_Register!$M$6:$M$205,$B13)&"") -> Narayanganj Board Mills | G13: =IF($B13="","",INDEX(Purchase_Register!$C$6:$C$205,$B13)&"") -> Cutting | H13: =IF($B13="","",INDEX(Purchase_Register!$BI$6:$BI$205,$B13)&"") -> In-house Closed - Payment Due | I13: =IF($B13="","",INDEX(Purchase_Register!$AX$6:$AX$205,$B13)&"") -> All In-house | J13: =IF($B13="","",N(INDEX(Purchase_Register!$AK$6:$AK$205,$B13))) -> 352800 | K13: =IF($B13="","",N(INDEX(Purchase_Register!$AL$6:$AL$205,$B13))) -> 0 | L13: =IF($B13="","",INDEX(Purchase_Register!$BK$6:$BK$205,$B13)&"") -> Pay supplier: 31 days overdue;
A14: =IF(ROWS($A$7:A14)>COUNT(Purchase_Register!$BM$6:$BM$205),"",ROWS($A$7:A14)) -> 8 | B14: =IF($A14="","",MATCH(SMALL(Purchase_Register!$BM$6:$BM$205,$A14),Purchase_Register!$BM$6:$BM$205,0)) -> 17 | C14: =IF($B14="","",INDEX(Purchase_Register!$BL$6:$BL$205,$B14)&"") -> High | D14: =IF($B14="","",INDEX(Purchase_Register!$A$6:$A$205,$B14)&"") -> PSIL-PR-2026-0017 | E14: =IF($B14="","",INDEX(Purchase_Register!$E$6:$E$205,$B14)&"") -> Sewing Machine Needles & Spares | F14: =IF($B14="","",INDEX(Purchase_Register!$M$6:$M$205,$B14)&"") -> Dhaka Spares & Tools | G14: =IF($B14="","",INDEX(Purchase_Register!$C$6:$C$205,$B14)&"") -> Maintenance | H14: =IF($B14="","",INDEX(Purchase_Register!$BI$6:$BI$205,$B14)&"") -> In-house Closed - Payment Due | I14: =IF($B14="","",INDEX(Purchase_Register!$AX$6:$AX$205,$B14)&"") -> All In-house | J14: =IF($B14="","",N(INDEX(Purchase_Register!$AK$6:$AK$205,$B14))) -> 40248 | K14: =IF($B14="","",N(INDEX(Purchase_Register!$AL$6:$AL$205,$B14))) -> 0 | L14: =IF($B14="","",INDEX(Purchase_Register!$BK$6:$BK$205,$B14)&"") -> Pay supplier: 25 days overdue; QC rejected: return / replace;
A15: =IF(ROWS($A$7:A15)>COUNT(Purchase_Register!$BM$6:$BM$205),"",ROWS($A$7:A15)) -> 9 | B15: =IF($A15="","",MATCH(SMALL(Purchase_Register!$BM$6:$BM$205,$A15),Purchase_Register!$BM$6:$BM$205,0)) -> 18 | C15: =IF($B15="","",INDEX(Purchase_Register!$BL$6:$BL$205,$B15)&"") -> High | D15: =IF($B15="","",INDEX(Purchase_Register!$A$6:$A$205,$B15)&"") -> PSIL-PR-2026-0018 | E15: =IF($B15="","",INDEX(Purchase_Register!$E$6:$E$205,$B15)&"") -> Safety PPE (Masks, Gloves, Goggles) | F15: =IF($B15="","",INDEX(Purchase_Register!$M$6:$M$205,$B15)&"") -> Dhaka Spares & Tools | G15: =IF($B15="","",INDEX(Purchase_Register!$C$6:$C$205,$B15)&"") -> Compliance & HSE | H15: =IF($B15="","",INDEX(Purchase_Register!$BI$6:$BI$205,$B15)&"") -> In-house Closed - Payment Due | I15: =IF($B15="","",INDEX(Purchase_Register!$AX$6:$AX$205,$B15)&"") -> All In-house | J15: =IF($B15="","",N(INDEX(Purchase_Register!$AK$6:$AK$205,$B15))) -> 107392.5 | K15: =IF($B15="","",N(INDEX(Purchase_Register!$AL$6:$AL$205,$B15))) -> 0 | L15: =IF($B15="","",INDEX(Purchase_Register!$BK$6:$BK$205,$B15)&"") -> Pay supplier: 36 days overdue;
A16: =IF(ROWS($A$7:A16)>COUNT(Purchase_Register!$BM$6:$BM$205),"",ROWS($A$7:A16)) -> 10 | B16: =IF($A16="","",MATCH(SMALL(Purchase_Register!$BM$6:$BM$205,$A16),Purchase_Register!$BM$6:$BM$205,0)) -> 24 | C16: =IF($B16="","",INDEX(Purchase_Register!$BL$6:$BL$205,$B16)&"") -> High | D16: =IF($B16="","",INDEX(Purchase_Register!$A$6:$A$205,$B16)&"") -> PSIL-PR-2026-0024 | E16: =IF($B16="","",INDEX(Purchase_Register!$E$6:$E$205,$B16)&"") -> Pig Lining Leather | F16: =IF($B16="","",INDEX(Purchase_Register!$M$6:$M$205,$B16)&"") -> Savar Leather Works Ltd | G16: =IF($B16="","",INDEX(Purchase_Register!$C$6:$C$205,$B16)&"") -> Cutting | H16: =IF($B16="","",INDEX(Purchase_Register!$BI$6:$BI$205,$B16)&"") -> In-house Closed - Payment Due | I16: =IF($B16="","",INDEX(Purchase_Register!$AX$6:$AX$205,$B16)&"") -> All In-house | J16: =IF($B16="","",N(INDEX(Purchase_Register!$AK$6:$AK$205,$B16))) -> 814188.17 | K16: =IF($B16="","",N(INDEX(Purchase_Register!$AL$6:$AL$205,$B16))) -> 0 | L16: =IF($B16="","",INDEX(Purchase_Register!$BK$6:$BK$205,$B16)&"") -> Pay supplier: 22 days overdue; QC rejected: return / replace;
A17: =IF(ROWS($A$7:A17)>COUNT(Purchase_Register!$BM$6:$BM$205),"",ROWS($A$7:A17)) -> 11 | B17: =IF($A17="","",MATCH(SMALL(Purchase_Register!$BM$6:$BM$205,$A17),Purchase_Register!$BM$6:$BM$205,0)) -> 33 | C17: =IF($B17="","",INDEX(Purchase_Register!$BL$6:$BL$205,$B17)&"") -> High | D17: =IF($B17="","",INDEX(Purchase_Register!$A$6:$A$205,$B17)&"") -> PSIL-PR-2026-0033 | E17: =IF($B17="","",INDEX(Purchase_Register!$E$6:$E$205,$B17)&"") -> Cow Nappa Upper Leather | F17: =IF($B17="","",INDEX(Purchase_Register!$M$6:$M$205,$B17)&"") -> Savar Leather Works Ltd | G17: =IF($B17="","",INDEX(Purchase_Register!$C$6:$C$205,$B17)&"") -> Cutting | H17: =IF($B17="","",INDEX(Purchase_Register!$BI$6:$BI$205,$B17)&"") -> Closed | I17: =IF($B17="","",INDEX(Purchase_Register!$AX$6:$AX$205,$B17)&"") -> Short Closed - 915 sqft not received | J17: =IF($B17="","",N(INDEX(Purchase_Register!$AK$6:$AK$205,$B17))) -> 0 | K17: =IF($B17="","",N(INDEX(Purchase_Register!$AL$6:$AL$205,$B17))) -> 281308 | L17: =IF($B17="","",INDEX(Purchase_Register!$BK$6:$BK$205,$B17)&"") -> Short closed: claim balance / credit note BDT 281,308;
A18: =IF(ROWS($A$7:A18)>COUNT(Purchase_Register!$BM$6:$BM$205),"",ROWS($A$7:A18)) -> 12 | B18: =IF($A18="","",MATCH(SMALL(Purchase_Register!$BM$6:$BM$205,$A18),Purchase_Register!$BM$6:$BM$205,0)) -> 34 | C18: =IF($B18="","",INDEX(Purchase_Register!$BL$6:$BL$205,$B18)&"") -> High | D18: =IF($B18="","",INDEX(Purchase_Register!$A$6:$A$205,$B18)&"") -> PSIL-PR-2026-0034 | E18: =IF($B18="","",INDEX(Purchase_Register!$E$6:$E$205,$B18)&"") -> PU Adhesive (Solvent Based) | F18: =IF($B18="","",INDEX(Purchase_Register!$M$6:$M$205,$B18)&"") -> Gazipur Chem Trade | G18: =IF($B18="","",INDEX(Purchase_Register!$C$6:$C$205,$B18)&"") -> Lasting & Assembly | H18: =IF($B18="","",INDEX(Purchase_Register!$BI$6:$BI$205,$B18)&"") -> In-house Closed - Payment Due | I18: =IF($B18="","",INDEX(Purchase_Register!$AX$6:$AX$205,$B18)&"") -> All In-house | J18: =IF($B18="","",N(INDEX(Purchase_Register!$AK$6:$AK$205,$B18))) -> 563730 | K18: =IF($B18="","",N(INDEX(Purchase_Register!$AL$6:$AL$205,$B18))) -> 0 | L18: =IF($B18="","",INDEX(Purchase_Register!$BK$6:$BK$205,$B18)&"") -> QC rejected: return / replace;
... A206: =IF(ROWS($A$7:A206)>COUNT(Purchase_Register!$BM$6:$BM$205),"",ROWS($A$7:A206)) | B206: =IF($A206="","",MATCH(SMALL(Purchase_Register!$BM$6:$BM$205,$A206),Purchase_Register!$BM$6:$BM$205,0)) | C206: =IF($B206="","",INDEX(Purchase_Register!$BL$6:$BL$205,$B206)&"") | D206: =IF($B206="","",INDEX(Purchase_Register!$A$6:$A$205,$B206)&"") | E206: =IF($B206="","",INDEX(Purchase_Register!$E$6:$E$205,$B206)&"") | F206: =IF($B206="","",INDEX(Purchase_Register!$M$6:$M$205,$B206)&"") | G206: =IF($B206="","",INDEX(Purchase_Register!$C$6:$C$205,$B206)&"") | H206: =IF($B206="","",INDEX(Purchase_Register!$BI$6:$BI$205,$B206)&"") | I206: =IF($B206="","",INDEX(Purchase_Register!$AX$6:$AX$205,$B206)&"") | J206: =IF($B206="","",N(INDEX(Purchase_Register!$AK$6:$AK$205,$B206))) | K206: =IF($B206="","",N(INDEX(Purchase_Register!$AL$6:$AL$205,$B206))) | L206: =IF($B206="","",INDEX(Purchase_Register!$BK$6:$BK$205,$B206)&"")

Sheet Purchase_Register
A1: PANDA SHOES INDUSTRY LTD — PURCHASE TRACKING REGISTER (PR → Approval → PO → In-house → Payment)
A2: BLACK cells with WHITE text = data entry (only these can be typed in). ORANGE = required input missing for this stage. GREY = automatic formula (locked). Check the 'Data Check' column — every line should read OK. Capacity: rows 6–205.
A3: ✎ INPUT | B3: ✎ INPUT | C3: ✎ INPUT | D3: ✎ INPUT | E3: ✎ INPUT | F3: ✎ INPUT | G3: ✎ INPUT | H3: ✎ INPUT | I3: ✎ INPUT | J3: ✎ INPUT | K3: ✎ INPUT | L3: ✎ INPUT | M3: ✎ INPUT | N3: ✎ INPUT | O3: ✎ INPUT | P3: ✎ INPUT | Q3: ✎ INPUT | R3: ✎ INPUT | S3: ✎ INPUT | T3: ✎ INPUT | U3: AUTO | V3: ✎ INPUT | W3: AUTO | X3: AUTO | Y3: AUTO | Z3: AUTO | AA3: AUTO | AB3: AUTO | AC3: ✎ INPUT | AD3: AUTO | AE3: ✎ INPUT | AF3: ✎ INPUT | AG3: ✎ INPUT | AH3: ✎ INPUT | AI3: AUTO | AJ3: AUTO | AK3: AUTO | AL3: AUTO | AM3: AUTO | AN3: ✎ INPUT | AO3: ✎ INPUT | AP3: AUTO | AQ3: AUTO | AR3: ✎ INPUT | AS3: ✎ INPUT | AT3: ✎ INPUT | AU3: AUTO | AV3: AUTO | AW3: AUTO | AX3: AUTO | AY3: ✎ INPUT | AZ3: AUTO | BA3: AUTO | BB3: AUTO | BC3: AUTO | BD3: AUTO | BE3: AUTO | BF3: ✎ INPUT | BG3: ✎ INPUT | BH3: ✎ INPUT | BI3: AUTO | BJ3: AUTO | BK3: AUTO | BL3: AUTO | BM3: AUTO | BN3: ✎ INPUT
A4: 1 · REQUISITION & OPEX/CAPEX APPROVAL | M4: 2 · PURCHASE ORDER & VALUE | AE4: 3 · FINANCE STATUS & PAYABLES | AR4: 4 · IN-HOUSE RECEIVING & CYCLE TIME | BF4: 5 · MATERIAL APPROVAL & STAGE
A5: PR No | B5: PR Received Date | C5: Department | D5: Requested By | E5: Item / Material Purchased | F5: Category | G5: Spec / Size / Colour | H5: Spend Type (OPEX / CAPEX) | I5: OPEX / CAPEX Approval Ref | J5: Approval Date | K5: Approval Status | L5: Approved By | M5: Supplier | N5: Local / Import | O5: PO No | P5: PO Date | Q5: Order Quantity | R5: UOM | S5: Unit Price (PO Currency) | T5: Currency | U5: FX Rate to BDT | V5: Budget / Standard Unit Price (BDT) | W5: PO Value (BDT) | X5: Unit Price (BDT) | Y5: Previous PO Unit Price — Same Item (BDT) | Z5: Price Change vs Previous PO % | AA5: Price Variance vs Budget (BDT) | AB5: Price Variance % | AC5: VAT / AIT / Duty % | AD5: Total Price incl. Tax (BDT) | AE5: Payment Terms | AF5: Initial / Advance Paid (BDT) | AG5: Interim Payment (BDT) | AH5: Closing Payment (BDT) | AI5: Total Paid (BDT) | AJ5: % of Payment | AK5: Outstanding Payable (BDT) | AL5: Paid Ahead of Receipt (BDT) | AM5: Finance Status | AN5: Last Payment Date | AO5: Next Payment Due Date | AP5: Days Payment Overdue | AQ5: Payable Aging Bucket | AR5: Supplier Committed Delivery Date | AS5: Starting to In-house Date | AT5: Qty Received In-house | AU5: Received % | AV5: Pending Qty to In-house | AW5: Pending In-house Value (BDT) | AX5: Pending Material Status | AY5: Final In-house Closing Date | AZ5: Days PR → Approval | BA5: Days Approval → PO | BB5: Lead Time PO → In-house Close (days) | BC5: Total Cycle PR → Close (days) | BD5: Delivery Delay (days) | BE5: OTIF | BF5: QC / Material Approval | BG5: Approved Material Photo — File / Link | BH5: Approved Material Picture | BI5: Current Stage | BJ5: Data Check (auto) | BK5: Action Required (auto) | BL5: Action Priority | BM5: Action Sort Key | BN5: Remarks
A6: PSIL-PR-2026-0001 | B6: 46175 | C6: Cutting | D6: Cutting Manager | E6: Cow Nappa Upper Leather | F6: Leather & Upper | G6: 1.2–1.4 mm, Black | H6: OPEX | I6: OPX-2026-101 | J6: 46176 | K6: Approved | L6: GM Operations | M6: Savar Leather Works Ltd | N6: Local | O6: PSIL-PO-2026-0001 | P6: 46181 | Q6: 10500 | R6: sqft | S6: 2.35 | T6: USD | U6: =IF(AND(T6="",S6=""),"",IF(T6="",1,IFERROR(INDEX(Settings!$B$12:$B$16,MATCH(T6,Settings!$A$12:$A$16,0)),1))) -> 122 | V6: 278.93 | W6: =IF(OR(Q6="",S6=""),"",Q6*S6*U6) -> 3010350 | X6: =IF(OR(W6="",N(Q6)=0),"",W6/Q6) -> 286.7 | Y6: =IF(OR(X6="",P6="",E6=""),"",IF(_xlfn.MAXIFS($P$6:$P$205,$E$6:$E$205,E6,$P$6:$P$205,"<"&P6,$X$6:$X$205,">0")=0,"",IFERROR(AVERAGEIFS($X$6:$X$205,$E$6:$E$205,E6,$P$6:$P$205,_xlfn.MAXIFS($P$6:$P$205,$E$6:$E$205,E6,$P$6:$P$205,"<"&P6,$X$6:$X$205,">0"),$X$6:$X$205,">0"),""))) | Z6: =IF(OR(Y6="",X6=""),"",X6/Y6-1) | AA6: =IF(OR(W6="",V6=""),"",W6-Q6*V6) -> 81585 | AB6: =IF(AA6="","",IF(N(V6)*N(Q6)=0,"",AA6/(Q6*V6))) -> 0.027856451 | AC6: 0.05 | AD6: =IF(W6="","",W6*(1+N(AC6))) -> 3160867.5 | AE6: 30% Advance / 70% after In-house | AF6: 948260.25 | AH6: 2212607.2 | AI6: =IF(A6="","",N(AF6)+N(AG6)+N(AH6)) -> 3160867.5 | AJ6: =IF(AD6="","",IF(N(AD6)=0,"",AI6/AD6)) -> 1 | AK6: =IF(AD6="","",IF(AD6-AI6<1,0,ROUND(AD6-AI6,2))) -> 0 | AL6: =IF(OR(O6="",AD6=""),"",MAX(0,ROUND(N(AI6)-(AD6-N(AW6)),0))) -> 0 | AM6: =IF(A6="","",IF(O6="","No PO Yet",IF(AI6=0,"Not Paid",IF(N(AJ6)>=0.999,"Fully Paid",IF(N(AG6)+N(AH6)>0,"Partially Paid","Initial / Advance Paid"))))) -> Fully Paid | AN6: 46203 | AP6: =IF(AK6="","",IF(OR(N(AK6)=0,AO6=""),"",MAX(0,Settings!$B$4-AO6))) | AQ6: =IF(AK6="","",IF(N(AK6)<=0,"",IF(AO6="","No Due Date",IF(Settings!$B$4<=AO6,"Not Yet Due",IF(Settings!$B$4-AO6<=30,"1-30 Days",IF(Settings!$B$4-AO6<=60,"31-60 Days",IF(Settings!$B$4-AO6<=90,"61-90 Days","90+ Days"))))))) | AR6: 46191 | AS6: 46188 | AT6: 10500 | AU6: =IF(Q6="","",IF(N(Q6)=0,"",N(AT6)/Q6)) -> 1 | AV6: =IF(OR(A6="",O6="",Q6=""),"",MAX(0,Q6-N(AT6))) -> 0 | AW6: =IF(OR(AV6="",W6=""),"",IF(N(Q6)=0,0,AV6/Q6*AD6)) -> 0 | AX6: =IF(A6="","",IF(O6="","No PO Yet",IF(Q6="","Order Qty Missing",IF(N(AT6)>=Q6,IF(N(AT6)>Q6,"All In-house (+"&TEXT(N(AT6)-Q6,"#,##0")&" "&R6&" excess)","All In-house"),IF(AY6<>"","Short Closed - "&TEXT(AV6,"#,##0")&" "&R6&" not received",IF(N(AT6)=0,"Not Started - "&TEXT(AV6,"#,##0")&" "&R6&" pending","Pending "&TEXT(AV6,"#,##0")&" "&R6&" ("&TEXT(AU6,"0%")&" received)")))))) -> All In-house | AY6: 46188 | AZ6: =IF(OR(B6="",J6=""),"",J6-B6) -> 1 | BA6: =IF(OR(J6="",P6=""),"",P6-J6) -> 5 | BB6: =IF(OR(P6="",AY6=""),"",AY6-P6) -> 7 | BC6: =IF(OR(B6="",AY6=""),"",AY6-B6) -> 13 | BD6: =IF(OR(AR6="",O6=""),"",MAX(0,IF(AY6="",Settings!$B$4,AY6)-AR6)) -> 0 | BE6: =IF(OR(AY6="",AR6=""),"",IF(AND(AY6<=AR6,N(AU6)>=Settings!$B$6),"OTIF","Not OTIF")) -> OTIF | BF6: Approved | BG6: Photos\PSIL-PR-2026-0001.jpg | BI6: =IF(A6="","",IF(K6="Rejected","Rejected",IF(K6<>"Approved","Awaiting Approval",IF(O6="","Approved - PO Pending",IF(AY6<>"",IF(N(AJ6)>=0.999,"Closed","In-house Closed - Payment Due"),IF(AS6<>"","Receiving In-house","PO Issued - Awaiting Delivery")))))) -> Closed | BJ6: =IF(A6="","",IF(IF(AND(A6<>"",OR(B6="",C6="",E6="",F6="",H6="")),"PR info missing; ","")&IF(AND(K6="Approved",OR(J6="",I6="")),"Approval ref/date missing; ","")&IF(AND(O6<>"",K6<>"Approved"),"PO without approval; ","")&IF(AND(O6<>"",OR(P6="",M6="",Q6="",S6="",T6="")),"PO details missing; ","")&IF(AND(O6<>"",AR6=""),"Committed date missing; ","")&IF(AND(ISNUMBER(J6),ISNUMBER(B6),N(J6)<N(B6)),"Approval dated before PR; ","")&IF(AND(ISNUMBER(P6),ISNUMBER(J6),N(P6)<N(J6)),"PO dated before approval; ","")&IF(AND(ISNUMBER(AY6),ISNUMBER(AS6),N(AY6)<N(AS6)),"Close before in-house start; ","")&IF(AND(AY6<>"",AS6=""),"In-house start date missing; ","")&IF(AND(AY6<>"",AT6=""),"Qty received missing; ","")&IF(AND(AY6<>"",BF6=""),"QC status missing; ","")&IF(N(AT6)>N(Q6)*1.05,"Received > ordered +5%; ","")&IF(AND(N(AI6)>0,AE6=""),"Payment terms missing; ","")&IF(N(AI6)>N(AD6)+1,"Overpaid vs PO; ","")&IF(AND(N(AK6)>0,AY6<>"",AO6=""),"Payment due date missing; ","")="","OK",IF(AND(A6<>"",OR(B6="",C6="",E6="",F6="",H6="")),"PR info missing; ","")&IF(AND(K6="Approved",OR(J6="",I6="")),"Approval ref/date missing; ","")&IF(AND(O6<>"",K6<>"Approved"),"PO without approval; ","")&IF(AND(O6<>"",OR(P6="",M6="",Q6="",S6="",T6="")),"PO details missing; ","")&IF(AND(O6<>"",AR6=""),"Committed date missing; ","")&IF(AND(ISNUMBER(J6),ISNUMBER(B6),N(J6)<N(B6)),"Approval dated before PR; ","")&IF(AND(ISNUMBER(P6),ISNUMBER(J6),N(P6)<N(J6)),"PO dated before approval; ","")&IF(AND(ISNUMBER(AY6),ISNUMBER(AS6),N(AY6)<N(AS6)),"Close before in-house start; ","")&IF(AND(AY6<>"",AS6=""),"In-house start date missing; ","")&IF(AND(AY6<>"",AT6=""),"Qty received missing; ","")&IF(AND(AY6<>"",BF6=""),"QC status missing; ","")&IF(N(AT6)>N(Q6)*1.05,"Received > ordered +5%; ","")&IF(AND(N(AI6)>0,AE6=""),"Payment terms missing; ","")&IF(N(AI6)>N(AD6)+1,"Overpaid vs PO; ","")&IF(AND(N(AK6)>0,AY6<>"",AO6=""),"Payment due date missing; ",""))) -> OK | BK6: =IF(A6="","",IF(N(AP6)>0,"Pay supplier: "&N(AP6)&" days overdue; ","")&IF(AND(O6<>"",AY6="",N(BD6)>0),"Expedite delivery: "&N(BD6)&" days late; ","")&IF(AND(BI6="Awaiting Approval",ISNUMBER(B6),Settings!$B$4-N(B6)>Settings!$B$19),"Get approval: PR waiting "&(Settings!$B$4-N(B6))&" days; ","")&IF(AND(BI6="Approved - PO Pending",ISNUMBER(J6),Settings!$B$4-N(J6)>Settings!$B$20),"Issue PO: approved "&(Settings!$B$4-N(J6))&" days ago; ","")&IF(AND(OR(BI6="Awaiting Approval",BI6="Approved - PO Pending"),N(AB6)>Settings!$B$7),"Negotiate price: "&TEXT(AB6,"0%")&" above budget; ","")&IF(LEFT(AX6,12)="Short Closed","Short closed: claim balance / credit note"&IF(N(AL6)>0," BDT "&TEXT(AL6,"#,##0"),"")&"; ","")&IF(BF6="Rejected","QC rejected: return / replace; ","")&IF(AND(O6<>"",AY6="",N(AL6)>0,N(BD6)>0),"Advance at risk: BDT "&TEXT(AL6,"#,##0")&" paid, goods late; ","")&IF(AND(BJ6<>"",BJ6<>"OK"),"Fix data entry (see Data Check); ","")) | BL6: =IF(BK6="","",IF(OR(N(AP6)>30,AND(AY6="",N(BD6)>15),BF6="Rejected",AND(LEFT(AX6,12)="Short Closed",N(AL6)>0),AND(O6<>"",AY6="",N(AL6)>0,N(BD6)>0)),"High",IF(OR(N(AP6)>0,AND(AY6="",N(BD6)>7),LEFT(AX6,12)="Short Closed",AND(BI6="Awaiting Approval",ISNUMBER(B6),Settings!$B$4-N(B6)>2*Settings!$B$19),AND(BI6="Approved - PO Pending",ISNUMBER(J6),Settings!$B$4-N(J6)>2*Settings!$B$20)),"Medium","Low"))) | BM6: =IF(BL6="","",IF(BL6="High",1,IF(BL6="Medium",2,3))*10000+ROW())
A7: PSIL-PR-2026-0002 | B7: 46178 | C7: Cutting | D7: Cutting Manager | E7: Suede Split Leather | F7: Leather & Upper | G7: 1.6 mm, Taupe | H7: OPEX | I7: OPX-2026-102 | J7: 46180 | K7: Approved | L7: CFO | M7: Savar Leather Works Ltd | N7: Local | O7: PSIL-PO-2026-0002 | P7: 46185 | Q7: 4500 | R7: sqft | S7: 1.76 | T7: USD | U7: =IF(AND(T7="",S7=""),"",IF(T7="",1,IFERROR(INDEX(Settings!$B$12:$B$16,MATCH(T7,Settings!$A$12:$A$16,0)),1))) -> 122 | V7: 196.76 | W7: =IF(OR(Q7="",S7=""),"",Q7*S7*U7) -> 966240 | X7: =IF(OR(W7="",N(Q7)=0),"",W7/Q7) -> 214.72 | Y7: =IF(OR(X7="",P7="",E7=""),"",IF(_xlfn.MAXIFS($P$6:$P$205,$E$6:$E$205,E7,$P$6:$P$205,"<"&P7,$X$6:$X$205,">0")=0,"",IFERROR(AVERAGEIFS($X$6:$X$205,$E$6:$E$205,E7,$P$6:$P$205,_xlfn.MAXIFS($P$6:$P$205,$E$6:$E$205,E7,$P$6:$P$205,"<"&P7,$X$6:$X$205,">0"),$X$6:$X$205,">0"),""))) | Z7: =IF(OR(Y7="",X7=""),"",X7/Y7-1) | AA7: =IF(OR(W7="",V7=""),"",W7-Q7*V7) -> 80820 | AB7: =IF(AA7="","",IF(N(V7)*N(Q7)=0,"",AA7/(Q7*V7))) -> 0.091278715 | AC7: 0.05 | AD7: =IF(W7="","",W7*(1+N(AC7))) -> 1014552 | AE7: 100% Advance | AF7: 1014552 | AI7: =IF(A7="","",N(AF7)+N(AG7)+N(AH7)) -> 1014552 | AJ7: =IF(AD7="","",IF(N(AD7)=0,"",AI7/AD7)) -> 1 | AK7: =IF(AD7="","",IF(AD7-AI7<1,0,ROUND(AD7-AI7,2))) -> 0 | AL7: =IF(OR(O7="",AD7=""),"",MAX(0,ROUND(N(AI7)-(AD7-N(AW7)),0))) -> 0 | AM7: =IF(A7="","",IF(O7="","No PO Yet",IF(AI7=0,"Not Paid",IF(N(AJ7)>=0.999,"Fully Paid",IF(N(AG7)+N(AH7)>0,"Partially Paid","Initial / Advance Paid"))))) -> Fully Paid | AN7: 46186 | AP7: =IF(AK7="","",IF(OR(N(AK7)=0,AO7=""),"",MAX(0,Settings!$B$4-AO7))) | AQ7: =IF(AK7="","",IF(N(AK7)<=0,"",IF(AO7="","No Due Date",IF(Settings!$B$4<=AO7,"Not Yet Due",IF(Settings!$B$4-AO7<=30,"1-30 Days",IF(Settings!$B$4-AO7<=60,"31-60 Days",IF(Settings!$B$4-AO7<=90,"61-90 Days","90+ Days"))))))) | AR7: 46204 | AS7: 46198 | AT7: 4500 | AU7: =IF(Q7="","",IF(N(Q7)=0,"",N(AT7)/Q7)) -> 1 | AV7: =IF(OR(A7="",O7="",Q7=""),"",MAX(0,Q7-N(AT7))) -> 0 | AW7: =IF(OR(AV7="",W7=""),"",IF(N(Q7)=0,0,AV7/Q7*AD7)) -> 0 | AX7: =IF(A7="","",IF(O7="","No PO Yet",IF(Q7="","Order Qty Missing",IF(N(AT7)>=Q7,IF(N(AT7)>Q7,"All In-house (+"&TEXT(N(AT7)-Q7,"#,##0")&" "&R7&" excess)","All In-house"),IF(AY7<>"","Short Closed - "&TEXT(AV7,"#,##0")&" "&R7&" not received",IF(N(AT7)=0,"Not Started - "&TEXT(AV7,"#,##0")&" "&R7&" pending","Pending "&TEXT(AV7,"#,##0")&" "&R7&" ("&TEXT(AU7,"0%")&" received)")))))) -> All In-house | AY7: 46199 | AZ7: =IF(OR(B7="",J7=""),"",J7-B7) -> 2 | BA7: =IF(OR(J7="",P7=""),"",P7-J7) -> 5 | BB7: =IF(OR(P7="",AY7=""),"",AY7-P7) -> 14 | BC7: =IF(OR(B7="",AY7=""),"",AY7-B7) -> 21 | BD7: =IF(OR(AR7="",O7=""),"",MAX(0,IF(AY7="",Settings!$B$4,AY7)-AR7)) -> 0 | BE7: =IF(OR(AY7="",AR7=""),"",IF(AND(AY7<=AR7,N(AU7)>=Settings!$B$6),"OTIF","Not OTIF")) -> OTIF | BF7: Rejected | BI7: =IF(A7="","",IF(K7="Rejected","Rejected",IF(K7<>"Approved","Awaiting Approval",IF(O7="","Approved - PO Pending",IF(AY7<>"",IF(N(AJ7)>=0.999,"Closed","In-house Closed - Payment Due"),IF(AS7<>"","Receiving In-house","PO Issued - Awaiting Delivery")))))) -> Closed | BJ7: =IF(A7="","",IF(IF(AND(A7<>"",OR(B7="",C7="",E7="",F7="",H7="")),"PR info missing; ","")&IF(AND(K7="Approved",OR(J7="",I7="")),"Approval ref/date missing; ","")&IF(AND(O7<>"",K7<>"Approved"),"PO without approval; ","")&IF(AND(O7<>"",OR(P7="",M7="",Q7="",S7="",T7="")),"PO details missing; ","")&IF(AND(O7<>"",AR7=""),"Committed date missing; ","")&IF(AND(ISNUMBER(J7),ISNUMBER(B7),N(J7)<N(B7)),"Approval dated before PR; ","")&IF(AND(ISNUMBER(P7),ISNUMBER(J7),N(P7)<N(J7)),"PO dated before approval; ","")&IF(AND(ISNUMBER(AY7),ISNUMBER(AS7),N(AY7)<N(AS7)),"Close before in-house start; ","")&IF(AND(AY7<>"",AS7=""),"In-house start date missing; ","")&IF(AND(AY7<>"",AT7=""),"Qty received missing; ","")&IF(AND(AY7<>"",BF7=""),"QC status missing; ","")&IF(N(AT7)>N(Q7)*1.05,"Received > ordered +5%; ","")&IF(AND(N(AI7)>0,AE7=""),"Payment terms missing; ","")&IF(N(AI7)>N(AD7)+1,"Overpaid vs PO; ","")&IF(AND(N(AK7)>0,AY7<>"",AO7=""),"Payment due date missing; ","")="","OK",IF(AND(A7<>"",OR(B7="",C7="",E7="",F7="",H7="")),"PR info missing; ","")&IF(AND(K7="Approved",OR(J7="",I7="")),"Approval ref/date missing; ","")&IF(AND(O7<>"",K7<>"Approved"),"PO without approval; ","")&IF(AND(O7<>"",OR(P7="",M7="",Q7="",S7="",T7="")),"PO details missing; ","")&IF(AND(O7<>"",AR7=""),"Committed date missing; ","")&IF(AND(ISNUMBER(J7),ISNUMBER(B7),N(J7)<N(B7)),"Approval dated before PR; ","")&IF(AND(ISNUMBER(P7),ISNUMBER(J7),N(P7)<N(J7)),"PO dated before approval; ","")&IF(AND(ISNUMBER(AY7),ISNUMBER(AS7),N(AY7)<N(AS7)),"Close before in-house start; ","")&IF(AND(AY7<>"",AS7=""),"In-house start date missing; ","")&IF(AND(AY7<>"",AT7=""),"Qty received missing; ","")&IF(AND(AY7<>"",BF7=""),"QC status missing; ","")&IF(N(AT7)>N(Q7)*1.05,"Received > ordered +5%; ","")&IF(AND(N(AI7)>0,AE7=""),"Payment terms missing; ","")&IF(N(AI7)>N(AD7)+1,"Overpaid vs PO; ","")&IF(AND(N(AK7)>0,AY7<>"",AO7=""),"Payment due date missing; ",""))) -> OK | BK7: =IF(A7="","",IF(N(AP7)>0,"Pay supplier: "&N(AP7)&" days overdue; ","")&IF(AND(O7<>"",AY7="",N(BD7)>0),"Expedite delivery: "&N(BD7)&" days late; ","")&IF(AND(BI7="Awaiting Approval",ISNUMBER(B7),Settings!$B$4-N(B7)>Settings!$B$19),"Get approval: PR waiting "&(Settings!$B$4-N(B7))&" days; ","")&IF(AND(BI7="Approved - PO Pending",ISNUMBER(J7),Settings!$B$4-N(J7)>Settings!$B$20),"Issue PO: approved "&(Settings!$B$4-N(J7))&" days ago; ","")&IF(AND(OR(BI7="Awaiting Approval",BI7="Approved - PO Pending"),N(AB7)>Settings!$B$7),"Negotiate price: "&TEXT(AB7,"0%")&" above budget; ","")&IF(LEFT(AX7,12)="Short Closed","Short closed: claim balance / credit note"&IF(N(AL7)>0," BDT "&TEXT(AL7,"#,##0"),"")&"; ","")&IF(BF7="Rejected","QC rejected: return / replace; ","")&IF(AND(O7<>"",AY7="",N(AL7)>0,N(BD7)>0),"Advance at risk: BDT "&TEXT(AL7,"#,##0")&" paid, goods late; ","")&IF(AND(BJ7<>"",BJ7<>"OK"),"Fix data entry (see Data Check); ","")) -> QC rejected: return / replace; | BL7: =IF(BK7="","",IF(OR(N(AP7)>30,AND(AY7="",N(BD7)>15),BF7="Rejected",AND(LEFT(AX7,12)="Short Closed",N(AL7)>0),AND(O7<>"",AY7="",N(AL7)>0,N(BD7)>0)),"High",IF(OR(N(AP7)>0,AND(AY7="",N(BD7)>7),LEFT(AX7,12)="Short Closed",AND(BI7="Awaiting Approval",ISNUMBER(B7),Settings!$B$4-N(B7)>2*Settings!$B$19),AND(BI7="Approved - PO Pending",ISNUMBER(J7),Settings!$B$4-N(J7)>2*Settings!$B$20)),"Medium","Low"))) -> High | BM7: =IF(BL7="","",IF(BL7="High",1,IF(BL7="Medium",2,3))*10000+ROW()) -> 10007
